Workbook

Sheet eAPTC_D0401_Upd
A1: Category | B1: Metric | C1: Value | D1: Status | E1: Unit | F1: Additional_Info
A2: # INSTRUCTIONS | C2: HOW TO USE: Rows starting with # are ignored by the dashboard; Dashboard Settings section controls header display - customize these values; Day 1 metrics use Status 'actual' or 'mock' (for tracking only not shown in UI); Day 2 metrics use Status 'on-track' 'watch' 'at-risk' or 'off-track' (shown as colored badges); Unit column uses % for percentages K for thousands M for millions or leave blank; Add custom categories by using any name for Day 1 or prefix with 'Day2 ' for Day 2 (e.g. 'Day2 Custom Category'); Delete or modify any rows as needed - dashboard updates dynamically
A3: # â”€â”€ DASHBOARD SETTINGS â”€â”€
A4: Dashboard Settings | B4: Data As Of Date | C4: Feb 16 2026 | F4: Customizable date shown in header
A5: Dashboard Settings | B5: Coverage Month | C5: 46048 | F5: Customizable coverage month text
A6: Dashboard Settings | B6: Coverage Effective Date | C6: Jan 1 2026 | F6: Customizable coverage effective date
A7: Global Payment | B7: Members Paid | C7: 737048 | D7: actual | F7: *Medical Only including fully subsidized
A8: Global Payment | B8: Planned Paid Members | C8: 961640 | D8: actual | F8: January coverage plan
A9: Global Payment | B9: Payment Performance vs Plan | C9: 100 | D9: actual | E9: % | F9: Paid Subscribers *1.3 / Planned Members
A10: Membership National | B10: New Sales Applications | C10: 585650 | D10: actual | F10: Total applications
A11: Membership National | B11: New Sales vs PY | C11: 459832 | D11: actual | F11: Prior year comparison
A12: Membership National | B12: New Sales vs PY Pct | C12: 27 | D12: actual | E12: % | F12: Year over year growth
A13: Membership National | B13: New Sales vs Plan | D13: actual | E13: %
A14: Membership National | B14: New Sales Bronze | C14: 52 | D14: actual | E14: %
A15: Membership National | B15: New Sales Silver | C15: 31 | D15: actual | E15: %
A16: Membership National | B16: New Sales Gold | C16: 16 | D16: actual | E16: %
A17: Membership National | B17: New Sales Platinum | C17: 2 | D17: actual | E17: %
A18: Membership National | B18: Active Renewals | C18: 247866 | D18: actual | F18: Total active renewals
A19: Membership National | B19: Active Renewals vs PY | C19: 209182 | D19: actual | F19: Prior year comparison
A20: Membership National | B20: Active Renewals vs PY Pct | C20: 18 | D20: actual | E20: % | F20: Year over year growth
A21: Membership National | B21: Active Renewals vs Plan | D21: actual | E21: %
A22: Membership National | B22: Active Renewals Bronze | C22: 48 | D22: actual | E22: %
A23: Membership National | B23: Active Renewals Silver | C23: 38 | D23: actual | E23: %
A24: Membership National | B24: Active Renewals Gold | C24: 12 | D24: actual | E24: %
A25: Membership National | B25: Active Renewals Platinum | C25: 1 | D25: actual | E25: %
A26: Membership National | B26: Passive Renewals | C26: 895220 | D26: actual | F26: Total passive renewals
A27: Membership National | B27: Passive Renewals vs PY | C27: 921937 | D27: actual | F27: Prior year comparison
A28: Membership National | B28: Passive Renewals vs PY Pct | C28: -3 | D28: actual | E28: % | F28: Year over year decline
A29: Membership National | B29: Passive Renewals vs Plan | D29: actual | E29: %
A30: Membership National | B30: Passive Renewals Bronze | C30: 35 | D30: actual | E30: %
A31: Membership National | B31: Passive Renewals Silver | C31: 54 | D31: actual | E31: %
A32: Membership National | B32: Passive Renewals Gold | C32: 10 | D32: actual | E32: %
A33: Membership National | B33: Passive Renewals Platinum | C33: 1 | D33: actual | E33: %
A34: Membership National | B34: Total Medical | C34: 1681694 | D34: actual | F34: vs PY 1590951(6%)
A35: Membership National | B35: Dental New Sales | C35: 126453 | D35: actual | F35: vs PY 139686(-9%)
A36: Membership National | B36: Vision New Sales | C36: 13906 | D36: actual | F36: vs PY 14998(-7%)
A37: Subsidy Profile | B37: YTD Applicants | C37: 544991 | D37: actual | F37: On-exchange new apps excl. mapped
A38: Subsidy Profile | B38: With APTC Subsidy | C38: 455466 | D38: actual | F38: 84% of applicants
A39: Subsidy Profile | B39: Highly Subsidized | C39: 36 | D39: actual | E39: % | F39: ?ëÑ98% premium covered
A40: Subsidy Profile | B40: Partially Subsidized 1-75 | C40: 17 | D40: mock | E40: % | F40: 1-75% premium
...

Sheet Sheet2
B1: Eligibility Count | C1: Billed | D1: Paid(AWD+Paper) | E1: Paper Grace | F1: Non-Pay | I1: Billed Total (metal wise) | J1: Paid Total (metal wise) | K1: Non APTC Grace Total (Metal wise) | L1: APTC Grace Total (Metal wise) | M1: Non-Pay Total (Metal wise) | N1: Bill Compare | O1: paid Compare | P1: Grace Compare | Q1: Non Pay Compare
A2: Jan | B2: =SUM(eAPTC_D0401_Upd!C223:C240) -> 862264 | C2: =SUM(eAPTC_D0401_Upd!C477:C494) -> 836266 | D2: =SUM(eAPTC_D0401_Upd!C1489:C1506,eAPTC_D0401_Upd!C1741:C1758) -> 721371 | E2: =SUM(eAPTC_D0401_Upd!C2245:C2262) -> 113487 | F2: =SUM(eAPTC_D0401_Upd!C984:C1001) -> 22356 | I2: =SUM(eAPTC_D0401_Upd!C2595:C2612,eAPTC_D0401_Upd!C2721:C2738,eAPTC_D0401_Upd!C2847:C2864,eAPTC_D0401_Upd!C2973:C2990) -> 836266 | J2: =SUM(eAPTC_D0401_Upd!C2613:C2630,eAPTC_D0401_Upd!C2739:C2756,eAPTC_D0401_Upd!C2865:C2882,eAPTC_D0401_Upd!C2991:C3008) -> 721371 | K2: =SUM(eAPTC_D0401_Upd!C2631:C2648,eAPTC_D0401_Upd!C2757:C2774,eAPTC_D0401_Upd!C2883:C2900,eAPTC_D0401_Upd!C3009:C3026) -> 90 | L2: =SUM(eAPTC_D0401_Upd!C2649:C2702,eAPTC_D0401_Upd!C2775:C2828,eAPTC_D0401_Upd!C2901:C2954,eAPTC_D0401_Upd!C3027:C3080) -> 113397 | M2: =SUM(eAPTC_D0401_Upd!C2703:C2720,eAPTC_D0401_Upd!C2829:C2846,eAPTC_D0401_Upd!C2955:C2972,eAPTC_D0401_Upd!C3081:C3098) -> 22356 | N2: =C2=I2 -> TRUE | O2: =D2=J2 -> TRUE | P2: =(K2+L2)=E2 -> TRUE | Q2: =F2=M2 -> TRUE
A3: Feb | B3: =SUM(eAPTC_D0401_Upd!C241:C258) -> 781689 | C3: =SUM(eAPTC_D0401_Upd!C495:C512) -> 764977 | D3: =SUM(eAPTC_D0401_Upd!C1507:C1524,eAPTC_D0401_Upd!C1759:C1776) -> 746551 | E3: =SUM(eAPTC_D0401_Upd!C2263:C2280) -> 15740 | F3: =SUM(eAPTC_D0401_Upd!C1002:C1019) -> 4078 | I3: =SUM(eAPTC_D0401_Upd!C3228:C3245,eAPTC_D0401_Upd!C3354:C3371,eAPTC_D0401_Upd!C3480:C3497,eAPTC_D0401_Upd!C3606:C3623) -> 764977 | J3: =SUM(eAPTC_D0401_Upd!C3246:C3263,eAPTC_D0401_Upd!C3372:C3389,eAPTC_D0401_Upd!C3498:C3515,eAPTC_D0401_Upd!C3624:C3641) -> 746551 | K3: =SUM(eAPTC_D0401_Upd!C3264:C3281,eAPTC_D0401_Upd!C3390:C3407,eAPTC_D0401_Upd!C3516:C3533,eAPTC_D0401_Upd!C3642:C3659) -> 546 | L3: =SUM(eAPTC_D0401_Upd!C3282:C3335,eAPTC_D0401_Upd!C3408:C3461,eAPTC_D0401_Upd!C3534:C3587,eAPTC_D0401_Upd!C3660:C3713) -> 15194 | M3: =SUM(eAPTC_D0401_Upd!C3336:C3353,eAPTC_D0401_Upd!C3462:C3479,eAPTC_D0401_Upd!C3588:C3605,eAPTC_D0401_Upd!C3714:C3731) -> 4078 | N3: =C3=I3 -> TRUE | O3: =D3=J3 -> TRUE | P3: =(K3+L3)=E3 -> TRUE | Q3: =F3=M3 -> TRUE
A4: Mar | B4: =SUM(eAPTC_D0401_Upd!C259:C276) -> 774746 | C4: =SUM(eAPTC_D0401_Upd!C513:C530) -> 751784 | D4: =SUM(eAPTC_D0401_Upd!C1525:C1542,eAPTC_D0401_Upd!C1777:C1794) -> 722912 | E4: =SUM(eAPTC_D0401_Upd!C2281:C2298) -> 19319 | F4: =SUM(eAPTC_D0401_Upd!C1020:C1037) -> 3 | I4: =SUM(eAPTC_D0401_Upd!C3987:C4004,eAPTC_D0401_Upd!C4113:C4130,eAPTC_D0401_Upd!C4239:C4256,eAPTC_D0401_Upd!C3861:C3878) -> 751784 | J4: =SUM(eAPTC_D0401_Upd!C3879:C3896,eAPTC_D0401_Upd!C4005:C4022,eAPTC_D0401_Upd!C4131:C4148,eAPTC_D0401_Upd!C4257:C4274) -> 722912 | K4: =SUM(eAPTC_D0401_Upd!C3897:C3914,eAPTC_D0401_Upd!C4023:C4040,eAPTC_D0401_Upd!C4149:C4166,eAPTC_D0401_Upd!C4275:C4292) -> 6503 | L4: =SUM(eAPTC_D0401_Upd!C3915:C3968,eAPTC_D0401_Upd!C4041:C4094,eAPTC_D0401_Upd!C4167:C4220,eAPTC_D0401_Upd!C4293:C4346) -> 12816 | M4: =SUM(eAPTC_D0401_Upd!C3969:C3986,eAPTC_D0401_Upd!C4095:C4112,eAPTC_D0401_Upd!C4221:C4238,eAPTC_D0401_Upd!C4347:C4364) -> 3 | N4: =C4=I4 -> TRUE | O4: =D4=J4 -> TRUE | P4: =(K4+L4)=E4 -> TRUE | Q4: =F4=M4 -> TRUE
A5: Apr | B5: =SUM(eAPTC_D0401_Upd!C277:C294) -> 761112 | C5: =SUM(eAPTC_D0401_Upd!C531:C548) -> 742813 | D5: =SUM(eAPTC_D0401_Upd!C1543:C1560,eAPTC_D0401_Upd!C1795:C1812) -> 582047 | E5: =SUM(eAPTC_D0401_Upd!C2299:C2316) -> 11988 | F5: =SUM(eAPTC_D0401_Upd!C1038:C1055) -> 0 | I5: =SUM(eAPTC_D0401_Upd!C4494:C4511,eAPTC_D0401_Upd!C4620:C4637,eAPTC_D0401_Upd!C4746:C4763,eAPTC_D0401_Upd!C4872:C4889) -> 742813 | J5: =SUM(eAPTC_D0401_Upd!C4512:C4529,eAPTC_D0401_Upd!C4638:C4655,eAPTC_D0401_Upd!C4764:C4781,eAPTC_D0401_Upd!C4890:C4907) -> 582047 | K5: =SUM(eAPTC_D0401_Upd!C4530:C4547,eAPTC_D0401_Upd!C4656:C4673,eAPTC_D0401_Upd!C4782:C4799,eAPTC_D0401_Upd!C4908:C4925) -> 3187 | L5: =SUM(eAPTC_D0401_Upd!C4548:C4601,eAPTC_D0401_Upd!C4674:C4727,eAPTC_D0401_Upd!C4800:C4853,eAPTC_D0401_Upd!C4926:C4979) -> 8801 | M5: =SUM(eAPTC_D0401_Upd!C4602:C4619,eAPTC_D0401_Upd!C4728:C4745,eAPTC_D0401_Upd!C4854:C4871,eAPTC_D0401_Upd!C4980:C4997) -> 0 | N5: =C5=I5 -> TRUE | O5: =D5=J5 -> TRUE | P5: =(K5+L5)=E5 -> TRUE | Q5: =F5=M5 -> TRUE
A6: May | B6: =SUM(eAPTC_D0401_Upd!C295:C312) -> 748640 | C6: =SUM(eAPTC_D0401_Upd!C549:C566) -> 268818 | D6: =SUM(eAPTC_D0401_Upd!C1561:C1578,eAPTC_D0401_Upd!C1813:C1830) -> 185427 | E6: =SUM(eAPTC_D0401_Upd!C2317:C2334) -> 0 | F6: =SUM(eAPTC_D0401_Upd!C1056:C1073) -> 0 | I6: =SUM(eAPTC_D0401_Upd!C5127:C5144,eAPTC_D0401_Upd!C5252:C5270,eAPTC_D0401_Upd!C5379:C5396,eAPTC_D0401_Upd!C5505:C5522) -> 268818 | J6: =SUM(eAPTC_D0401_Upd!C5145:C5162,eAPTC_D0401_Upd!C5271:C5288,eAPTC_D0401_Upd!C5397:C5414,eAPTC_D0401_Upd!C5523:C5540) -> 185427 | K6: =SUM(eAPTC_D0401_Upd!C5163:C5180,eAPTC_D0401_Upd!C5289:C5306,eAPTC_D0401_Upd!C5415:C5432,eAPTC_D0401_Upd!C5541:C5558) -> 0 | L6: =SUM(eAPTC_D0401_Upd!C5181:C5234,eAPTC_D0401_Upd!C5307:C5360,eAPTC_D0401_Upd!C5433:C5486,eAPTC_D0401_Upd!C5559:C5612) -> 0 | M6: =SUM(eAPTC_D0401_Upd!C5235:C5252,eAPTC_D0401_Upd!C5361:C5378,eAPTC_D0401_Upd!C5487:C5504,eAPTC_D0401_Upd!C5613:C5630) -> 0 | N6: =C6=I6 -> TRUE | O6: =D6=J6 -> TRUE | P6: =(K6+L6)=E6 -> TRUE | Q6: =F6=M6 -> TRUE
A9: Nov | B9: =SUM(eAPTC_D0401_Upd!C403:C420) -> 863742 | C9: =SUM(eAPTC_D0401_Upd!C657:C674) -> 862183 | D9: =SUM(eAPTC_D0401_Upd!C1669:C1686,eAPTC_D0401_Upd!C1921:C1938) -> 860069 | E9: =SUM(eAPTC_D0401_Upd!C2425:C2442) -> 617 | F9: =SUM(eAPTC_D0401_Upd!C1164:C1181,eAPTC_D0401_Upd!C1416:C1433) -> 14835 | I9: =SUM(eAPTC_D0401_Upd!C8925:C8942,eAPTC_D0401_Upd!C9051:C9068,eAPTC_D0401_Upd!C9177:C9194,eAPTC_D0401_Upd!C9303:C9320) -> 862183 | J9: =SUM(eAPTC_D0401_Upd!C8943:C8960,eAPTC_D0401_Upd!C9069:C9086,eAPTC_D0401_Upd!C9195:C9212,eAPTC_D0401_Upd!C9321:C9338) -> 860069 | K9: =SUM(eAPTC_D0401_Upd!C8961:C8978,eAPTC_D0401_Upd!C9087:C9104,eAPTC_D0401_Upd!C9213:C9230,eAPTC_D0401_Upd!C9339:C9356) -> 231 | L9: =SUM(eAPTC_D0401_Upd!C8979:C9032,eAPTC_D0401_Upd!C9105:C9158,eAPTC_D0401_Upd!C9231:C9284,eAPTC_D0401_Upd!C9357:C9410) -> 386 | M9: =SUM(eAPTC_D0401_Upd!C9033:C9050,eAPTC_D0401_Upd!C9159:C9176,eAPTC_D0401_Upd!C9285:C9302,eAPTC_D0401_Upd!C9411:C9428) -> 14835 | N9: =C9=I9 -> TRUE | O9: =D9=J9 -> TRUE | P9: =(K9+L9)=E9 -> TRUE | Q9: =F9=M9 -> TRUE
A10: Dec | B10: =SUM(eAPTC_D0401_Upd!C421:C438) -> 848158 | C10: =SUM(eAPTC_D0401_Upd!C675:C692) -> 836154 | D10: =SUM(eAPTC_D0401_Upd!C1687:C1704,eAPTC_D0401_Upd!C1939:C1956) -> 831287 | E10: =SUM(eAPTC_D0401_Upd!C2443:C2460) -> 1778 | F10: =SUM(eAPTC_D0401_Upd!C1182:C1199,eAPTC_D0401_Upd!C1434:C1451) -> 13247 | I10: =SUM(eAPTC_D0401_Upd!C9558:C9575,eAPTC_D0401_Upd!C9684:C9701,eAPTC_D0401_Upd!C9810:C9827,eAPTC_D0401_Upd!C9936:C9953) -> 836154 | J10: =SUM(eAPTC_D0401_Upd!C9576:C9593,eAPTC_D0401_Upd!C9702:C9719,eAPTC_D0401_Upd!C9828:C9845,eAPTC_D0401_Upd!C9954:C9971) -> 831287 | K10: =SUM(eAPTC_D0401_Upd!C9594:C9611,eAPTC_D0401_Upd!C9720:C9737,eAPTC_D0401_Upd!C9846:C9863,eAPTC_D0401_Upd!C9972:C9989) -> 495 | L10: =SUM(eAPTC_D0401_Upd!C9612:C9665,eAPTC_D0401_Upd!C9738:C9791,eAPTC_D0401_Upd!C9864:C9917,eAPTC_D0401_Upd!C9990:C10043) -> 1283 | M10: =SUM(eAPTC_D0401_Upd!C9666:C9683,eAPTC_D0401_Upd!C9792:C9809,eAPTC_D0401_Upd!C9918:C9935,eAPTC_D0401_Upd!C10044:C10061) -> 13247 | N10: =C10=I10 -> TRUE | O10: =D10=J10 -> TRUE | P10: =(K10+L10)=E10 -> TRUE | Q10: =F10=M10 -> TRUE
